Workbook

Sheet consolidado
A1: codigoOC | B1: FechaEnvioOC | C1: NombreOC | D1: DescripcionOC | E1: MontoNetoOC | F1: DescuentosOC | G1: CargosOC | H1: ImpuestosOC | I1: MontoTotalOC | J1: UnidadCompra | K1: Proveedor | L1: ProveedorRUT | M1: ActividadProveedor | N1: TamanoProveedor | O1: RegionProveedor | P1: CodigoProductoONU | Q1: DescripcionItem | R1: CantidadItem | S1: UnidadMedida | T1: MontoNetoItem | U1: MontoTotalItem | V1: CodigoCotizacion | W1: DescripcionCotizacion | X1: CodigoProductoCotizadoONU | Y1: RUTProveedorCotizacion | Z1: DetalleCotizacion
A2: 1058012-6724-AG25 | B2: 45934 | C2: URGENTE FARMACIA DOSIS UNITARIA ABRIL / BENRALIZUMAB 30 MG JGA | D2: PEDIDO URGENTE FARMACIA DOSIS UNITARIA ABRIL. COMPRA AGIL DESPACHO AEREO CARGO DEL PROVEEDOR. 1058012-191-COT25 | E2: 3189516 | F2: 0 | G2: 0 | H2: 606008.04 | I2: 3795524 | J2: Fármarcos | K2: ASTRAZENECA SA | L2: 76.447.530-5 | M2: VENTA AL POR MAYOR DE PRODUCTOS FARMACEUTICOS | N2: Grande | O2: Región Metropolitana de Santiago | P2: 85121902 | Q2: BENRALIZUMAB 30 MG JERINGA PRELLENADA | R2: 2 | S2: Unidad | T2: 1594758 | U2: 3189516 | V2: 1058012-191-COT25 | W2: EL HOSPITAL CLÍNICO DE MAGALLANES REQUIERE BENRALIZUMAB 30 MG JGA. INDICAR AL COTIZAR: VALOR UNITARIO TOTAL, PRESENTACIÓN (UD), FECHA VCTO, ADJUNTAR FICHA TÉCNICA Y/O REGISTRO ISP, TIPO DE TRASLADO (ESPECIFICAR, PARA ACORDAR RETIRO CARGO HOSPITAL DE SER NECESARIO), E INDICAR SI CUENTA CON STOCK PARA DESPACHO INMEDIATO. SE DECLARARÁ INADMISIBLE OFERTA QUE INDIQUE VALOR REFERENCIAL $0 o $1, U OMITAN CUALQUIER INFORMACIÓN SOLICITADA PARA ESTA COTIZACIÓN. | X2: 85121902 | Y2: 76.447.530-5 | Z2: Fármaco innovador y/o referente. Venc > 1 año, despacho 2-3 días hábiles desde aceptación de orden de compra. Flete incluido. Cuando genere su OC, el rut de compra y dirección de despacho deben poseer autorización sanitaria vigente.
A3: 1058012-1778-AG24 | B3: 45495 | C3: (FAR) COMITÉ FARMACIA JULIO / RILPIVIRINA - CABOTEGRAVIR 900-600 MG FA | D3: PEDIDO COMITÉ FARMACIA JULIO. ADQUISICIÓN VÍA COMPRA ÁGIL. FLETE 72 HORAS HÁBILES SEGÚN COTIZACIÓN. REF 1058012-497-COT24. | E3: 1518000 | F3: 0 | G3: 0 | H3: 288420 | I3: 1806420 | J3: Fármarcos | K3: GLAXOSMITHKLINE CHILE FARMACEUTICA LIMITADA | L3: 85.025.700-0 | M3: FABRICACION DE PRODUCTOS FARMACEUTICOS, SUSTANCIAS QUIMICAS MEDICINALE | N3: Grande | O3: Región Metropolitana de Santiago | P3: 85121902 | Q3: RILPIRIVINA - CABOTEGRAVIR 900-600 MG FA | R3: 3 | S3: Frasco Ampolla | T3: 506000 | U3: 1518000 | V3: 1058012-497-COT24 | W3: EL HOSPITAL CLÍNICO DE MAGALLANES REQUIERE RILPIRIVINA - CABOTEGRAVIR 900-600 MG FA. INDICAR AL COTIZAR: VALOR UNITARIO TOTAL, PRESENTACIÓN (FA), FECHA VCTO, ADJUNTAR FICHA TÉCNICA Y/O REGISTRO ISP, TIPO DE TRASLADO CARGO PROVEEDOR (ESPECIFICAR, PARA ACORDAR RETIRO CARGO HOSPITAL DE SER NECESARIO), E INDICAR SI CUENTA CON STOCK PARA DESPACHO INMEDIATO. SE DESESTIMARÁ OFERTA QUE INDIQUE VALOR REFERENCIAL $0 o $1, U OMITAN INFORMACIÓN. | X3: 85121902 | Y3: 85.025.700-0 | Z3: Validez de la oferta 90 días. Facturación mínima $250.000.- neto. Vencimiento superior a doce meses, ENTREGA: 72Horas hábiles una vez aceptada la orden de compra. Condiciones Comerciales, Flete incluido. contacto gsk.ordenesdecompra@gsk.com
A4: 1058012-61-AG24 | B4: 45627 | C4: COMITÉ FARMACIA N°10 AÑO 2023/ RILPIRIVINA - CABOTEGRAVIR 900-600 MG FA | D4: PEDIDO COMITÉ FARMACIA N°10 AÑO 2023. COMPRA AGIL. FLETE AEREO CARGO DEL PROVEEDOR 1058012-15-COT24 | E4: 1518000 | F4: 0 | G4: 0 | H4: 288420 | I4: 1806420 | J4: Fármarcos | K4: GLAXOSMITHKLINE CHILE FARMACEUTICA LIMITADA | L4: 85.025.700-0 | M4: FABRICACION DE PRODUCTOS FARMACEUTICOS, SUSTANCIAS QUIMICAS MEDICINALE | N4: Grande | O4: Región Metropolitana de Santiago | P4: 51191905 | Q4: RILPIRIVINA - CABOTEGRAVIR 900-600 MG FA | R4: 3 | S4: Frasco Ampolla | T4: 506000 | U4: 1518000 | V4: 1058012-15-COT24 | W4: EL HOSPITAL CLÍNICO DE MAGALLANES REQUIERE CABOTEGRAVIR/RILPIVIRINA 600/900 MF FA. INDICAR AL COTIZAR: VALOR UNITARIO TOTAL, PRESENTACIÓN (ML), FECHA VCTO, ADJUNTAR FICHA TÉCNICA Y/O REGISTRO ISP, TIPO DE TRASLADO (ESPECIFICAR, PARA ACORDAR RETIRO CARGO HOSPITAL DE SER NECESARIO), E INDICAR SI CUENTA CON STOCK PARA DESPACHO INMEDIATO. SE DESESTIMARÁ OFERTA QUE INDIQUE VALOR REFERENCIAL $0 o $1, U OMITAN INFORMACIÓN. | X4: 51191905 | Y4: 85.025.700-0 | Z4: Validez de la oferta 90 días. Facturación mínima $250.000.- neto. Vencimiento superior a doce meses, ENTREGA: 48 Horas hábiles una vez aceptada la orden de compra. Políticas de Devolución punto d), Flete incluido. contacto gsk.ordenesdecompra@gsk.com
A5: 1058012-7475-AG25 | B5: 45825 | C5: FALTA CENABAST FARMACIA AMBULATORIA JUNIO / DENOSUMAB 60 MG ML SOL INY | D5: PEDIDO FALTA CENABAST FARMACIA AMBULATORIA JUNIO. ADQUISICIÓN VÍA COMPRA ÁGIL. DESPACHO 7 DÍAS CARGO DEL PROVEEDOR SEGÚN COTIZACIÓN. ZGEN 100004663. REF 1058012-408-COT25. | E5: 564448 | F5: 0 | G5: 0 | H5: 107245.12 | I5: 671693.12 | J5: Fármarcos | K5: SCM PHARMA SPA | L5: 77.337.544-5 | M5: VENTA AL POR MAYOR DE PRODUCTOS FARMACEUTICOS Y MEDICINALES | N5: Mediana | O5: Región Metropolitana de Santiago | P5: 85121902 | Q5: DENOSUMAB 60 MG ML SOLUCIÓN INYECTABLE | R5: 2 | S5: Frasco Ampolla | T5: 282224 | U5: 564448 | V5: 1058012-408-COT25 | W5: EL HOSPITAL CLÍNICO DE MAGALLANES REQUIERE DENOSUMAB 60 MG ML SOL INY. INDICAR AL COTIZAR: VALOR UNITARIO TOTAL, PRESENTACIÓN (UD), FECHA VCTO, ADJUNTAR FICHA TÉCNICA Y/O REGISTRO ISP, TIPO DE TRASLADO Y FECHA ESPECIFICA DE ENTREGA (ESPECIFICAR, PARA ACORDAR RETIRO CARGO HOSPITAL DE SER NECESARIO), E INDICAR SI CUENTA CON STOCK PARA DESPACHO INMEDIATO. SE DECLARARÁ INADMISIBLE OFERTA QUE INDIQUE VALOR REFERENCIAL $0 o $1, U OMITAN INFORMACIÓN Y DOCUMENTOS SOLICITADOS. | X5: 85121902 | Y5: 77.337.544-5 | Z5: Se adjunta cotización detallada, Contacto F. 225104550, contacto@scmpharma.cl, Despacho sin costo, Envio 7 dias- monto mínimo de despacho $ 100.000.- Cotización valida por 15 días.
A6: 1058012-7755-AG25 | B6: 45859 | C6: FALTA CENABAST (SUSPENDIDO) JULIO / DENOSUMAB 60 MG ML SOL INY | D6: PEDIDO FALTA CENABAST (SUSPENDIDO) JULIO. ADQUISICIÓN VÍA COMPRA ÁGIL. DESPACHO 7 DÍAS CARGO DEL PROVEEDOR SEGÚN COTIZACIÓN. ZGEN 100004663. REF 1058012-465-COT25. | E6: 1128896 | F6: 0 | G6: 0 | H6: 214490.24 | I6: 1343386.2 | J6: Fármarcos | K6: SCM PHARMA SPA | L6: 77.337.544-5 | M6: VENTA AL POR MAYOR DE PRODUCTOS FARMACEUTICOS Y MEDICINALES | N6: Mediana | O6: Región Metropolitana de Santiago | P6: 85121902 | Q6: DENOSUMAB 60 MG ML SOLUCIÓN INYECTABLE | R6: 4 | S6: Unidad | T6: 282224 | U6: 1128896 | V6: 1058012-465-COT25 | W6: EL HOSPITAL CLÍNICO DE MAGALLANES REQUIERE DENOSUMAB 60 MG ML SOL INY. INDICAR AL COTIZAR: VALOR UNITARIO TOTAL, PRESENTACIÓN (UD), FECHA VCTO, ADJUNTAR FICHA TÉCNICA Y/O REGISTRO ISP, TIPO DE TRASLADO (ESPECIFICAR, PARA ACORDAR RETIRO CARGO HOSPITAL DE SER NECESARIO), E INDICAR SI CUENTA CON STOCK PARA DESPACHO INMEDIATO. SE DECLARARÁ INADMISIBLE OFERTA QUE INDIQUE VALOR REFERENCIAL $1, U OMITAN INFORMACIÓN Y DOCUMENTOS SOLICITADOS. | X6: 85121902 | Y6: 77.337.544-5 | Z6: Se adjunta cotización detallada, Contacto F. 225104550, contacto@scmpharma.cl, Despacho sin costo, Envio 7 dias- monto mínimo de despacho $ 100.000.- Cotización valida por 15 días.
A7: 1058012-1513-AG24 | B7: 45462 | C7: FARMACIA DOSIS UNITARIA/ IBUPROFENO 10 MG/2 ML AMP | D7: PEDIDO FARMACIA DOSIS UNITARIA.COMPRA AGIL DESPACHO AÉREO, CARGO DEL PROVEEDOR. 1058012-420-COT24 | E7: 1580000 | F7: 0 | G7: 0 | H7: 300200 | I7: 1880200 | J7: Fármarcos | K7: innovative medicines s.a . agencia en chile | L7: 59.144.890-0 | M7: venta al por menor de productos medicinales | N7: Mediana | O7: Región Metropolitana de Santiago | P7: 51142106 | Q7: IBUPROFENO 10 MG/2 ML AMP | R7: 8 | S7: Ampolla | T7: 197500 | U7: 1580000 | V7: 1058012-420-COT24 | W7: EL HOSPITAL CLÍNICO DE MAGALLANES REQUIERE IBUPROFENO 10 MG/2 ML AMP . INDICAR AL COTIZAR: VALOR UNITARIO TOTAL, PRESENTACIÓN (ML), FECHA VCTO, ADJUNTAR FICHA TÉCNICA Y/O REGISTRO ISP, TIPO DE TRASLADO y ESPECIFICAR FECHA DE ENTREGA, INDICAR SI CUENTA CON STOCK PARA DESPACHO INMEDIATO. SE DESESTIMARÁ OFERTA QUE INDIQUE VALOR REFERENCIAL $0 o $1, U OMITAN INFORMACIÓN. | X7: 51142106 | Y7: 59.144.890-0 | Z7: PRODUCTO PEDEA, autorizado en Chile bajo Resolución Exenta N° 33509 (adjunta), unidades en Chile disponibles para despacho inmediato, vencimiento 31.12.2025.
A8: 1058012-862-AG24 | B8: 45600 | C8: COMITÉ FARMACIA / CARBOXIMALTOSA DE HIERRO SOLUCIÓN INYECTABLE 500 MG/10 ML, AMP | D8: PEDIDO COMITÉ FARMACIA. COMPRA ÁGIL DESPACHO AÉREO CARGO DEL PROVEEDOR. 1058012-269-COT24 | E8: 141500 | F8: 0 | G8: 0 | H8: 26885 | I8: 168385 | J8: Fármarcos | K8: LABORATORIOS ANDROMACO S.A. | L8: 76.237.266-5 | M8: FARMACEUTICO | N8: Grande | O8: Región Metropolitana de Santiago | P8: 51131514 | Q8: CARBOXIMALTOSA DE HIERRO SOLUCIÓN INYECTABLE 500 MG/10 ML, AMP | R8: 1 | S8: Unidad | T8: 141500 | U8: 141500 | V8: 1058012-269-COT24 | W8: EL HOSPITAL CLÍNICO DE MAGALLANES REQUIERE CARBOXIMALTOSA DE HIERRO SOLUCIÓN INYECTABLE 500 MG/10 ML, AMP. INDICAR AL COTIZAR: VALOR UNITARIO TOTAL, PRESENTACIÓN (ML), FECHA VCTO, ADJUNTAR FICHA TÉCNICA Y/O REGISTRO ISP, TIPO DE TRASLADO (ESPECIFICAR, PARA ACORDAR RETIRO CARGO HOSPITAL DE SER NECESARIO), E INDICAR SI CUENTA CON STOCK PARA DESPACHO INMEDIATO. SE DESESTIMARÁ OFERTA QUE INDIQUE VALOR REFERENCIAL $0 o $1, U OMITAN INFORMACIÓN. | X8: 51131514 | Y8: 76.237.266-5 | Z8: 22100383 FERINJECT SOLUCION INYECTABLE 500/10 ML - 500MG DE HIERRO COMO CARBOXIMALTOSA DE HIERRO - FRASCO DE SOLUCION INYECTABLE REG. ISP F-20175/23, FECHA DE VCTO 30-06-2026, DESPACHO EN 02 D?AS MONTO M?NIMO DE DESPACHO $300.000 NETO
A9: 1058012-7375-AG25 | B9: 45936 | C9: COMPRA ALTERNATIVA (7225) FALTA CENABAST/ RISPERIDONA 37,5 MG FA POLVO LIOFILIZADO | D9: PEDIDO COMPRA ALTERNATIVA(7225). COMPRA AGIL. DESPACHO A CARGO DEL PROVEEDOR. 1058012-380-COT25 | E9: 1300000 | F9: 0 | G9: 0 | H9: 247000 | I9: 1547000 | J9: Fármarcos | K9: LABORATORIO C&D PHARMA LIMITADA | L9: 76.394.174-4 | M9: VENTA AL POR MAYOR DE PRODUCTOS FARMACEUTICOS | N9: Mediana | O9: Región Metropolitana de Santiago | P9: 51141704 | Q9: RISPERIDONA 37,5 MG FA POLVO LIOFILIZADO | R9: 10 | S9: Frasco Ampolla | T9: 130000 | U9: 1300000 | V9: 1058012-380-COT25 | W9: EL HCM REQUIERE RISPERIDONA 37,5 MG FA POLVO LIOFILIZADO. INDICAR FECHA DE ENTREGA EN BODEGA HCM, FACTOR EMPAQUE, FECHA VCTO, ADJUNTAR FICHA TÉCNICA Y/O REGISTRO ISP, TIPO DE TRASLADO. POSTULAR SOLO SI CUENTA CON STOCK PARA DESPACHO INMEDIATO. COMPRA SUJETA A MULTA DE NO RESPETAR FECHA ESTIMADA DE ENTREGA. SE DESESTIMARÁ OFERTA QUE INDIQUE VALOR REFERENCIAL $1, O QUE SOBREPASE EL VALOR DEL MONTO ESTIMADO O NO CUMPLA CON LOS DIAS Y DOC. SOLICITADOS. | X9: 51141704 | Y9: 76.394.174-4 | Z9: RISTRIONA RISPERIDONA POLVO PARA SUSPENSIÓN INYECTABLE DE LIBERACIÓN PROLONGADA 37,5 mg CON SOLVENTE REG ISP F-27100/22 FABRICANTE: LABORATORIO PHARMATHEN S.A., GRECIA PERIODO DE EFICACIA, 24 MESES
A10: 1058012-4803-AG25 | B10: 45747 | C10: FARMACIA AMBULATORIA MARZO / FLUTICASONA 50 MCG INH | D10: PEDIDO FARMACIA AMBULATORIA MARZO. ADQUISICIÓN VÍA COMPRA ÁGIL. DESPACHO 48 HRS. SEGÚN COTIZACIÓN. REF 1058012-161-COT25. | E10: 2100030 | F10: 0 | G10: 0 | H10: 399005.7 | I10: 2499035.7 | J10: Fármarcos | K10: FARMACIAS PEDRO ITURRIETA MELENDEZ E.I.R.L. | L10: 76.764.759-K | N10: Pequeña | O10: Región Metropolitana de Santiago | P10: 51181722 | Q10: FLUTICASONA 50 MCG INHALADOR BUCAL (ASMA BRONQUIAL) | R10: 30 | S10: Unidad | T10: 70001 | U10: 2100030 | V10: 1058012-161-COT25 | W10: EL HOSPITAL CLÍNICO DE MAGALLANES REQUIERE FLUTICASONA 50 MCG INHALADOR BUCAL (ASMA BRONQUIAL). INDICAR AL COTIZAR: VALOR UNITARIO TOTAL, PRESENTACIÓN (UD), FECHA VCTO, ADJUNTAR FICHA TÉCNICA Y/O REGISTRO ISP, TIPO DE TRASLADO CARGO PROVEEDOR (ESPECIFICAR, PARA ACORDAR RETIRO CARGO HOSPITAL DE SER NECESARIO), E INDICAR SI CUENTA CON STOCK PARA DESPACHO INMEDIATO. SE DECLARARÁ INADMISIBLE OFERTA QUE INDIQUE VALOR REFERENCIAL $0 o $1, U OMITAN INFORMACIÓN Y DOCUMENTOS SOLICITADOS. | X10: 51181722 | Y10: 76.764.759-K | Z10: BREXOVENT LF INHBUC 50 MCG X 120 DSS vence 4/26 despacho GRATIS 48 horas una vez aceptada al OC se adjunta ficha fono: 992657125
A11: 1058012-67-AG24 | B11: 45627 | C11: COMITÉ FARMACIA/ RILUZOL 5 MG/ML JBE | D11: PEDIDO COMITÉ FARMACIA. COMPRA AGIL. FLETE CARGO DEL PROVEEDOR. COORDINAR CON RODRIGO BARRIA AL 61-2293466 1058012-20-COT24 | E11: 271060 | F11: 0 | G11: 0 | H11: 51501.4 | I11: 322561.4 | J11: Fármarcos | K11: LABORATORIO CELNOVA CHILE SPA | L11: 76.926.592-9 | M11: Farmacéutico | N11: Pequeña | O11: Región Metropolitana de Santiago | P11: 51142801 | Q11: RILUZOL 5 MG/ML JBE | R11: 4 | S11: Frasco | T11: 67765 | U11: 271060 | V11: 1058012-20-COT24 | W11: EL HOSPITAL CLÍNICO DE MAGALLANES REQUIERE RILUZOL 5 MG/ML JBE. INDICAR AL COTIZAR: VALOR UNITARIO TOTAL, PRESENTACIÓN (ML), FECHA VCTO, ADJUNTAR FICHA TÉCNICA Y/O REGISTRO ISP, TIPO DE TRASLADO (ESPECIFICAR, PARA ACORDAR RETIRO CARGO HOSPITAL DE SER NECESARIO), E INDICAR SI CUENTA CON STOCK PARA DESPACHO INMEDIATO. SE DESESTIMARÁ OFERTA QUE INDIQUE VALOR REFERENCIAL $0 o $1, U OMITAN INFORMACIÓN. | X11: 51142801 | Y11: 76.926.592-9 | Z11: TEGLUTIK SUSPENSIÓN ORAL 5 mg/mL (RILUZOL). Presentación: solución oral 5 mg/ml, frasco 300 ml. Vencimiento: 31-07-2025. Tipo de traslado: Aéreo, temperatura ambiente, despacho en 48 horas habiles. Contamos con Stock inmediato.
A12: 1058012-7371-AG25 | B12: 45906 | C12: FALTA CENABAST / GLUCAGON 1MG LIOF SOL INYECT FAM | D12: PEDIDO FALTA CENABAST. COMPRA AGIL. DESPACHO A CARGO DEL PROVEEDOR. 1058012-372-COT25 | E12: 526900 | F12: 0 | G12: 0 | H12: 100111 | I12: 627011 | J12: Fármarcos | K12: LABORATORIO ACONFAR CHILE LIMITADA | L12: 76.125.564-9 | M12: SERVICIOS DE ENVASADO Y EMPAQUE| OTROS PROFESIONALES DE LA SALUD| OTRAS ACTIVIDADES EMPRESARIALES RELACIONADAS CON LA SALUD HUMANA | N12: Pequeña | O12: Región Metropolitana de Santiago | P12: 51181508 | Q12: GLUCAGON 1MG LIOF SOL INYECT FAM | R12: 10 | S12: Frasco Ampolla | T12: 52690 | U12: 526900 | V12: 1058012-372-COT25 | W12: EL HCM REQUIERE GLUCAGON 1MG LIOF SOL INYECT FAM. INDICAR FECHA DE ENTREGA EN BODEGA HCM, FACTOR EMPAQUE, FECHA VCTO, ADJUNTAR FICHA TÉCNICA Y/O REGISTRO ISP, TIPO DE TRASLADO. POSTULAR SOLO SI CUENTA CON STOCK PARA DESPACHO INMEDIATO. COMPRA SUJETA A MULTA DE NO RESPETAR FECHA ESTIMADA DE ENTREGA. SE DESESTIMARÁ OFERTA QUE INDIQUE VALOR REFERENCIAL $1, O QUE SOBREPASE EL VALOR DEL MONTO ESTIMADO O NO CUMPLA CON LOS DIAS Y DOC. SOLICITADOS. | X12: 51181508 | Y12: 76.125.564-9 | Z12: JOR. FACTURACION MINIMA $50.000+IVA PARA SANTIAGO Y $75.000+IVA PARA REGIONES, DESPACHO: STGO 24-48 HR Y REGIONES 72 HR, UNIDAD MIN. COTIZADA, SE AJUSTARÁ A FACTOR DE EMPAQUE, REG.ISP, FACT.ELECTRONICA. STOCK DISPONIBLE PARA ENTREGA INMEDIATA.
A13: 1058012-2929-AG24 | B13: 45577 | C13: FARMACIA AMBULATORIA DICIEMBRE / SOFOSBUVIR-VELPATASVIR 400-100 MG CM | D13: PEDIDO FARMACIA AMBULATORIA DICIEMBRE. ADQUISICIÓN VÍA COMPRA ÁGIL. FLETE 3 DÍAS HÁBILES CARGO DEL PROVEEDOR. REF 1058012-671-COT24. | E13: 1428000 | F13: 0 | G13: 0 | H13: 271320 | I13: 1699320 | J13: Fármarcos | K13: GADOR LIMITADA | L13: 76.084.945-6 | M13: FABRICACION DE PRODUCTOS FARMACEUTICOS, SUSTANCIAS QUIMICAS MEDICINALE| FABRICACION DE OTROS PRODUCTOS QUIMICOS N.C.P.| FABRICACION DE EQUIPO MEDICO Y QUIRURGICO, Y DE APARATOS ORTOPEDICOS| VENTA AL POR MAYOR DE OTROS PRODUCTOS N.C.P. | N13: Grande | O13: Región Metropolitana de Santiago | P13: 85121902 | Q13: SOFOSBUVIR-VELPATASVIR 400-100 MG CM | R13: 28 | S13: Comprimido | T13: 51000 | U13: 1428000 | V13: 1058012-671-COT24 | W13: EL HOSPITAL CLÍNICO DE MAGALLANES REQUIERE SOFOSBUVIR-VELPATASVIR 400-100 MG CM. INDICAR AL COTIZAR: VALOR UNITARIO TOTAL, PRESENTACIÓN (CM), FECHA VCTO, ADJUNTAR FICHA TÉCNICA Y/O REGISTRO ISP, TIPO DE TRASLADO CARGO PROVEEDOR (ESPECIFICAR, PARA ACORDAR RETIRO CARGO HOSPITAL DE SER NECESARIO), E INDICAR SI CUENTA CON STOCK PARA DESPACHO INMEDIATO. SE DESESTIMARÁ OFERTA QUE INDIQUE VALOR REFERENCIAL $0 o $1, U OMITAN INFORMACIÓN Y DOCUMENTOS SOLICITADOS. | X13: 85121902 | Y13: 76.084.945-6 | Z13: EPCLUSA 400/100 COMPRIMIDOS RECUBIERTOS SOFOSBUVIR 400 mg - VELPATASVIR 100mg, REFERENTE Estuche contiene 28 comprimidos recubiertos, Reg. ISP.- F-23583-22, Vcto: 30-04-2027, Plazo Entrega: 3 días hábiles, PRECIO ESTUCHE:$1.428.000
A14: 1058012-3013-AG24 | B14: 45645 | C14: FARMACIA AMBULATORIA URGENTE DICIEMBRE / SOFOSBUVIR-VELPATASVIR 400-100 MG CM | D14: PEDIDO FARMACIA AMBULATORIA URGENTE DICIEMBRE . COMPRA AGIL DESPACHO AÉREO CARGO DEL PROVEEDOR. 1058012-684-COT24 | E14: 2856000 | F14: 0 | G14: 0 | H14: 542640 | I14: 3398640 | J14: Fármarcos | K14: GADOR LIMITADA | L14: 76.084.945-6 | M14: FABRICACION DE PRODUCTOS FARMACEUTICOS, SUSTANCIAS QUIMICAS MEDICINALE| FABRICACION DE OTROS PRODUCTOS QUIMICOS N.C.P.| FABRICACION DE EQUIPO MEDICO Y QUIRURGICO, Y DE APARATOS ORTOPEDICOS| VENTA AL POR MAYOR DE OTROS PRODUCTOS N.C.P. | N14: Grande | O14: Región Metropolitana de Santiago | P14: 85121902 | Q14: SOFOSBUVIR-VELPATASVIR 400-100 MG CM | R14: 56 | S14: Comprimido | T14: 51000 | U14: 2856000 | V14: 1058012-684-COT24 | W14: EL HOSPITAL CLÍNICO DE MAGALLANES REQUIERE SOFOSBUVIR-VELPATASVIR 400-100 MG CM. INDICAR AL COTIZAR: VALOR UNITARIO TOTAL, PRESENTACIÓN (CM), FECHA VCTO, ADJUNTAR FICHA TÉCNICA Y/O REGISTRO ISP, TIPO DE TRASLADO CARGO PROVEEDOR (ESPECIFICAR, PARA ACORDAR RETIRO CARGO HOSPITAL DE SER NECESARIO), E INDICAR SI CUENTA CON STOCK PARA DESPACHO INMEDIATO. SE DESESTIMARÁ OFERTA QUE INDIQUE VALOR REFERENCIAL $0 o $1, U OMITAN INFORMACIÓN Y DOCUMENTOS SOLICITADOS. | X14: 85121902 | Y14: 76.084.945-6 | Z14: EPCLUSA 400/100 COMPRIMIDOS RECUBIERTOS SOFOSBUVIR 400 mg - VELPATASVIR 100mg, REFERENTE Estuche contiene 28 comprimidos recubiertos, Reg. ISP.- F-23583/22, Vcto: 30-04-2027, Plazo Ent: 3 dias hábiles, Valor ofertado x Unidad. STOCK DESPACHO INMEDIATO
A15: 1058012-7820-AG25 | B15: 45862 | C15: FARMACIA DU JULIO / METILPREDNISOLONA ACETATO 80 MG | D15: FARMACIA DU JULIO ADQUISICION A TRAVES DE COMPRA AGIL DESPACHO 24 A 48 HORAS CARGO DEL PROVEEDOR 100001027 REF: 1058012-459-COT25 | E15: 1303820 | F15: 0 | G15: 0 | H15: 247725.8 | I15: 1551545.8 | J15: Fármarcos | K15: PFIZER CHILE S.A. | L15: 96.981.250-9 | M15: FABRICACION DE PRODUCTOS DE CONFITERIA| FABRICACION DE PRODUCTOS FARMACEUTICOS, SUSTANCIAS QUIMICAS MEDICINALE| FABRICACIONES DE JABONES Y DETERGENTES, PREPARADOS PARA LIMPIAR, PERFU | N15: Grande | O15: Región Metropolitana de Santiago | P15: 51181707 | Q15: METILPREDNISOLONA ACETATO 80 MG. | R15: 35 | S15: Ampolla | T15: 37252 | U15: 1303820 | V15: 1058012-459-COT25 | W15: EL HCM REQUIERE METILPREDNISOLONA ACETATO 80 MG. INDICAR FECHA DE ENTREGA EN BODEGA HCM, FACTOR EMPAQUE, FECHA VCTO, ADJUNTAR FICHA TÉCNICA Y/O REGISTRO ISP, TIPO DE TRASLADO. POSTULAR SOLO SI CUENTA CON STOCK PARA DESPACHO INMEDIATO. COMPRA SUJETA A MULTA DE NO RESPETAR FECHA ESTIMADA DE ENTREGA. SE DESESTIMARÁ OFERTA QUE INDIQUE VALOR REFERENCIAL $1, O QUE SOBREPASE EL VALOR DEL MONTO ESTIMADO O NO CUMPLA CON LOS DIAS Y DOC. SOLICITADOS. | X15: 51181707 | Y15: 96.981.250-9 | Z15: DEPOMEDROL 80MG - ML - METILPREDNISOLONA. de PFIZER. Precio corresponde a 1 frasco ampolla. Envase de venta caja x 1 Frasco Ampolla. REGISTRO ISP N° F-1276-23 Vencimiento 31-05-2026. Con carta de canje.
A16: 1058012-845-AG24 | B16: 45539 | C16: PEDIDO FARMACIA DOSIS UNITARIA/ METILPREDNISOLONA ACETATO 80 MG | D16: PEDIDO F. DOSIS UNITARIA. COMPRA AGIL DESPACHO AÉREO CARGO DEL PROVEEDOR. 1058012-262-COT24 100001027 | E16: 1419120 | F16: 0 | G16: 0 | H16: 269632.8 | I16: 1688752.8 | J16: Fármarcos | K16: PFIZER CHILE S.A. | L16: 96.981.250-9 | M16: FABRICACION DE PRODUCTOS DE CONFITERIA| FABRICACION DE PRODUCTOS FARMACEUTICOS, SUSTANCIAS QUIMICAS MEDICINALE| FABRICACIONES DE JABONES Y DETERGENTES, PREPARADOS PARA LIMPIAR, PERFU | N16: Grande | O16: Región Metropolitana de Santiago | P16: 51181707 | Q16: METILPREDNISOLONA ACETATO 80 MG | R16: 40 | S16: Unidad | T16: 35478 | U16: 1419120 | V16: 1058012-262-COT24 | W16: EL HOSPITAL CLÍNICO DE MAGALLANES REQUIERE METILPREDNISOLONA ACETATO 80 MG. INDICAR AL COTIZAR: VALOR UNITARIO TOTAL, PRESENTACIÓN (ML), FECHA VCTO, ADJUNTAR FICHA TÉCNICA Y/O REGISTRO ISP, TIPO DE TRASLADO (ESPECIFICAR, PARA ACORDAR RETIRO CARGO HOSPITAL DE SER NECESARIO), E INDICAR SI CUENTA CON STOCK PARA DESPACHO INMEDIATO. SE DESESTIMARÁ OFERTA QUE INDIQUE VALOR REFERENCIAL $0 o $1, U OMITAN INFORMACIÓN. | X16: 51181707 | Y16: 96.981.250-9 | Z16: DEPOMEDROL 80MG - ML - METILPREDNISOLONA. de PFIZER. Precio corresponde a 1 frasco ampolla. Envase de venta caja x 1 F A. REG ISP N° F-1276-23. Vencimiento 31-07-2025. Flete incluido en el precio.
A17: 1058012-7670-AG25 | B17: 45845 | C17: FARMACIA AMBULATORIA JULIO / PANCREOLIPASA 5.000 UI GRANULOS | D17: PEDIDO FARMACIA AMBULATORIA JULIO. ADQUISICIÓN VÍA COMPRA ÁGIL. DESPACHO 3 DÍAS CARGO DEL PROVEEDOR SEGÚN COTIZACIÓN. REF 1058012-447-COT25. | E17: 1044150 | F17: 0 | G17: 0 | H17: 198388.5 | I17: 1242538.5 | J17: Fármarcos | K17: LABORATORIOS RECALCINE SA | L17: 91.637.000-8 | M17: FABRICACION DE PRODUCTOS FARMACEUTICOS, SUSTANCIAS QUIMICAS MEDICINALE| VENTA AL POR MAYOR DE OTROS PRODUCTOS N.C.P.| OTRAS ACTIVIDADES EMPRESARIALES N.C.P. | N17: Grande | O17: Región Metropolitana de Santiago | P17: 51171910 | Q17: PANCREOLIPASA 5.000 UI GRANULOS FRASCO 20 GR. | R17: 30 | S17: Frasco | T17: 34805 | U17: 1044150 | V17: 1058012-447-COT25 | W17: EL HOSPITAL CLÍNICO DE MAGALLANES REQUIERE PANCREOLIPASA 5.000 UI GRANULOS FRASCO 20 GR. INDICAR AL COTIZAR: VALOR UNITARIO TOTAL, PRESENTACIÓN (FCO), FECHA VCTO, ADJUNTAR FICHA TÉCNICA Y/O REGISTRO ISP, TIPO DE TRASLADO Y FECHA ESPECIFICA DE ENTREGA (ESPECIFICAR, PARA ACORDAR RETIRO CARGO HOSPITAL DE SER NECESARIO), E INDICAR SI CUENTA CON STOCK PARA DESPACHO INMEDIATO. SE DECLARARÁ INADMISIBLE OFERTA QUE INDIQUE VALOR REFERENCIAL $0 o $1, U OMITAN INFORMACIÓN Y DOCUMENTOS SOLICITADOS. | X17: 51171910 | Y17: 91.637.000-8 | Z17: 882352 CREON 5.000 FRASCO 20 MG PA PANCREATINA REG ISP B-2707/23 VENCE 30-04-2027 STOCK DESPACHO INMEDIATO COTIZACIÓN LABORATORIOS RECALCINE FLETE INCLUIDO DESPACHO EN 2 DÍAS/48 HORAS MÍN DE FACTURACIÓN 100.000 SE COTIZAN VALORES NETOS
A18: 1058012-1806-AG24 | B18: 45499 | C18: (FAR) COMPRA ALTERNATIVA STOCK CRÍTICO FARMACIA AMBULATORIA JUNIO / FLUTICASONA PROPIONATO MICRONIZADO 50 MCG INH ORAL | D18: COMPRA ALTERNATIVA POR FALTA DE STOCK EN PROVEEDOR OC N° 1058012-1651-AG24. FLETE 3 DÍAS SEGÚN COTIZACIÓN. REF 1058012-506-COT24. | E18: 1339650 | F18: 0 | G18: 0 | H18: 254533.5 | I18: 1594183.5 | J18: Fármarcos | K18: DROGUERÍA ACONCAGUA SPA | L18: 76.985.933-0 | M18: VENTA AL POR MAYOR DE PRODUCTOS FARMACEUTICOS Y MEDICINALES | N18: Micro | O18: Región Metropolitana de Santiago | P18: 51181722 | Q18: FLUTICASONA PROPIONATO MICRONIZADO 50 MCG AEROSOL PARA INHALACION ORAL (SIN ALCOHOL) | R18: 39 | S18: Unidad | T18: 34350 | U18: 1339650 | V18: 1058012-506-COT24 | W18: EL HOSPITAL CLÍNICO DE MAGALLANES REQUIERE FLUTICASONA PROPIONATO MICRONIZADO 50 MCG INH ORAL. INDICAR AL COTIZAR: VALOR UNITARIO TOTAL, PRESENTACIÓN (ML), FECHA VCTO, ADJUNTAR FICHA TÉCNICA Y/O REGISTRO ISP, TIPO DE TRASLADO CARGO PROVEEDOR (ESPECIFICAR, PARA ACORDAR RETIRO CARGO HOSPITAL DE SER NECESARIO), E INDICAR SI CUENTA CON STOCK PARA DESPACHO INMEDIATO. SE DESESTIMARÁ OFERTA QUE INDIQUE VALOR REFERENCIAL $0 o $1, U OMITAN INFORMACIÓN Y DOCUMENTOS SOLICITADOS. | X18: 51181722 | Y18: 76.985.933-0 | Z18: SE ADJUNTA COTIZACIÓN FORMAL Y FICHA DE PRODUCTO CON VENCE MAYOR A 12 MESES. PLAZO DE ENTREGA 2 A 3 DÍAS LUEGO DE EMITIDA LA ÓRDEN DE COMPRA. MÍNIMO DE DESPACHO 180.000 PESOS. REPRESENTANTE DE VENTA MARCEL ACUÑA. 9 75770902 VENTAS2@DROGUERIAACONCAGUA.CL
A19: 1058012-1651-AG24 | B19: 45298 | C19: STOCK CRÍTICO FARMACIA AMBULATORIA JUNIO / FLUTICASONA PROPIONATO MICRONIZADO 50 MCG INH ORAL | D19: PEDIDO STOCK CRÍTICO FARMACIA AMBULATORIA JUNIO. ADQUISICIÓN VÍA COMPRA ÁGIL. FLETE 48 HRS. SEGÚN COTIZACIÓN. REF 1058012-457-COT24 | E19: 1363520 | F19: 0 | G19: 0 | H19: 259068.8 | I19: 1622588.8 | J19: Fármarcos | K19: ADN FARMACEUTICA SPA | L19: 76.786.297-0 | M19: DROGUERIA | N19: Micro | O19: Región Metropolitana de Santiago | P19: 51181722 | Q19: FLUTICASONA PROPIONATO MICRONIZADO 50 MCG AEROSOL PARA INHALACION ORAL (SIN ALCOHOL) | R19: 40 | S19: Unidad | T19: 34088 | U19: 1363520 | V19: 1058012-457-COT24 | W19: EL HOSPITAL CLÍNICO DE MAGALLANES REQUIERE FLUTICASONA PROPIONATO MICRONIZADO 50 MCG AEROSOL PARA INHALACION ORAL (SIN ALCOHOL). INDICAR AL COTIZAR: VALOR UNITARIO TOTAL, PRESENTACIÓN (UD), FECHA VCTO, ADJUNTAR FICHA TÉCNICA Y/O REGISTRO ISP, TIPO DE TRASLADO CARGO PROVEEDOR (ESPECIFICAR, PARA ACORDAR RETIRO CARGO HOSPITAL DE SER NECESARIO), E INDICAR SI CUENTA CON STOCK PARA DESPACHO INMEDIATO. SE DESESTIMARÁ OFERTA QUE INDIQUE VALOR REFERENCIAL $0 o $1, U OMITAN INFORMACIÓN. | X19: 51181722 | Y19: 76.786.297-0 | Z19: FLIXOTIDE LF INH 50 MCG X 120 DS*ENTREGA DE 24 A 48 HORAS, VENCE SUPERIOR A 12 MESES, DESPACHO INCLUIDO EN EL PRECIO, SIN MINIMO DE COMPRA, OFERENTE Ximena Silva/9-57438894/xsilva@adnfarmaceutica.cl
A20: 1058012-7391-AG25 | B20: 45936 | C20: FALTA CENABAST JUNIO/METILPREDNISOLONA 1 G LIOF IV-IM FAM | D20: PEDIDO FALTA CENABAST JUNIO. COMPRA ÁGIL. DESPACHO A CARGO DEL PROVEEDOR. 1058012-374-COT25 | E20: 646627 | F20: 0 | G20: 0 | H20: 122859.13 | I20: 769486.13 | J20: Fármarcos | K20: PFIZER CHILE S.A. | L20: 96.981.250-9 | M20: FABRICACION DE PRODUCTOS DE CONFITERIA| FABRICACION DE PRODUCTOS FARMACEUTICOS, SUSTANCIAS QUIMICAS MEDICINALE| FABRICACIONES DE JABONES Y DETERGENTES, PREPARADOS PARA LIMPIAR, PERFU | N20: Grande | O20: Región Metropolitana de Santiago | P20: 51181707 | Q20: METILPREDNISOLONA 1G LIOF IV-IM FAN | R20: 19 | S20: Frasco Ampolla | T20: 34033 | U20: 646627 | V20: 1058012-374-COT25 | W20: EL HCM REQUIERE METILPREDNISOLONA 1G LIOF IV-IM FAN. INDICAR FECHA DE ENTREGA EN BODEGA HCM, FACTOR EMPAQUE, FECHA VCTO, ADJUNTAR FICHA TÉCNICA Y/O REGISTRO ISP, TIPO DE TRASLADO. POSTULAR SOLO SI CUENTA CON STOCK PARA DESPACHO INMEDIATO. COMPRA SUJETA A MULTA DE NO RESPETAR FECHA ESTIMADA DE ENTREGA. SE DESESTIMARÁ OFERTA QUE INDIQUE VALOR REFERENCIAL $1, O QUE SOBREPASE EL VALOR DEL MONTO ESTIMADO O NO CUMPLA CON LOS DIAS Y DOC. SOLICITADOS. | X20: 51181707 | Y20: 96.981.250-9 | Z20: SOLU MEDROL 1 GR ACT-O-VIAL METILPREDNISOLONA HEMISUCCINATO DE PFIZER. Precio corresponde a 1 frasco ampolla. Envase de venta caja x 1 frasco Ampolla. REGISTRO ISP N° F-2816-24. Vencimiento: 30-09-2026. MONTO MINIMO PARA DESPACHO 100.000
A21: 1058012-7390-AG25 | B21: 45936 | C21: FALTA CENABAST/DESMOPRESINA 100 MCG/1ML FRA 5 A 6 ML | D21: PEDIDO FALTA CENABAST. COMPRA ÁGIL. DESPACHO A CARGO DEL PROVEEDOR. 1058012-370-COT25 | E21: 168750 | F21: 0 | G21: 0 | H21: 32062.5 | I21: 200812.5 | J21: Fármarcos | K21: BPH S.A. | L21: 96.519.830-k | M21: VENTA AL POR MAYOR DE PRODUCTOS QUIMICOS | N21: Grande | O21: Región Metropolitana de Santiago | P21: 51182101 | Q21: DESMOPRESINA 100 MCG/1ML FRA 5 A 6 ML | R21: 5 | S21: Frasco | T21: 33750 | U21: 168750 | V21: 1058012-370-COT25 | W21: EL HCM REQUIERE DESMOPRESINA 100 MCG/1ML FRA 5 A 6 ML. INDICAR FECHA DE ENTREGA EN BODEGA HCM, FACTOR EMPAQUE, FECHA VCTO, ADJUNTAR FICHA TÉCNICA Y/O REGISTRO ISP, TIPO DE TRASLADO. POSTULAR SOLO SI CUENTA CON STOCK PARA DESPACHO INMEDIATO. COMPRA SUJETA A MULTA DE NO RESPETAR FECHA ESTIMADA DE ENTREGA. SE DESESTIMARÁ OFERTA QUE INDIQUE VALOR REFERENCIAL $1, O QUE SOBREPASE EL VALOR DEL MONTO ESTIMADO O NO CUMPLA CON LOS DIAS Y DOC. SOLICITADOS. | X21: 51182101 | Y21: 96.519.830-k | Z21: DESMOPRESINA ACET. SLN NASAL 10 MCG/D FC 5 ML EAN:7800086789003 VC:31-12-2026 REG:F-26040 EX1.SE COTIZA PRECIO NETO POR FC PARA DESPACHO 2 DIAS, MONTO MINIMO A FACTURAR Y DESPACHAR $120.000 NETO. PIA MARTINICH VENTAS6@BPH.CL
A22: 1058012-1512-AG24 | B22: 45461 | C22: COMITÉ FARMACIA MAYO / AMBRISENTÁN 10 MG CM | D22: PEDIDO COMITÉ FARMACIA MAYO. ADQUISICIÓN VÍA COMPRA ÁGIL. FLETE 3 DÍA HÁBILES SEGÚN COTIZACIÓN. REF 1058012-370-COT24. COMITÉ FARMACIA N°4 DEL 29-04-2024. | E22: 994440 | F22: 0 | G22: 0 | H22: 188943.6 | I22: 1183383.6 | J22: Fármarcos | K22: GLAXOSMITHKLINE CHILE FARMACEUTICA LIMITADA | L22: 85.025.700-0 | M22: FABRICACION DE PRODUCTOS FARMACEUTICOS, SUSTANCIAS QUIMICAS MEDICINALE | N22: Grande | O22: Región Metropolitana de Santiago | P22: 85121902 | Q22: AMBRISENTAM 10 MG CM | R22: 30 | S22: Comprimido | T22: 33148 | U22: 994440 | V22: 1058012-370-COT24 | W22: EL HOSPITAL CLÍNICO DE MAGALLANES REQUIERE AMBRISENTAM 10 MG CM. INDICAR AL COTIZAR: VALOR UNITARIO TOTAL, PRESENTACIÓN (CM), FECHA VCTO, ADJUNTAR FICHA TÉCNICA Y/O REGISTRO ISP, TIPO DE TRASLADO CARGO PROVEEDOR. (ESPECIFICAR, PARA ACORDAR RETIRO CARGO HOSPITAL DE SER NECESARIO), E INDICAR SI CUENTA CON STOCK PARA DESPACHO INMEDIATO. SE DESESTIMARÁ OFERTA QUE INDIQUE VALOR REFERENCIAL $0 o $1, U OMITAN INFORMACIÓN Y NO ADJUNTEN DOCUMENTOS. | X22: 85121902 | Y22: 85.025.700-0 | Z22: 60000000109532 VOLIBRIS 10mg x 30 Comprimidos recubiertos (I) AMBRISENTÁN VENCIMIENTO:Mayor a 12 Meses - ISP: F-22308/20. Despacho 3 días hábiles. Monto mínimo $250.000 Netos.
... A26: 1058012-3977-AG23 | B26: 45323 | C26: FARMACIA PROG. VIH / LECHE SUSTITUTA DE LECHE MATERNA | D26: PEDIDO FARMACIA [PROGR. VIH]. ADQUISIÓN VÍA COMPRA ÁGIL. FLETE CARGO DEL PROVEEDOR. REF 1058012-766-COT23 | E26: 1238400 | F26: 0 | G26: 0 | H26: 235296 | I26: 1473696 | J26: Fármarcos | K26: ACQUA INVERSIONES SPA | L26: 77.423.498-5 | M26: VENTA AL POR MAYOR NO ESPECIALIZADA | N26: N/A | O26: Región Metropolitana de Santiago | P26: 51191603 | Q26: LECHE SUSTITUTA DELECHE MATERNA NAN 1 800 GR. | R26: 48 | S26: Tarro | T26: 25800 | U26: 1238400 | V26: 1058012-766-COT23 | W26: EL HOSPITAL CLÍNICO DE MAGALLANES REQUIERE LECHE SUSTITUTA DELECHE MATERNA NAN 1 900 GR.. INDICAR AL COTIZAR: VALOR UNITARIO TOTAL, PRESENTACIÓN (GR), FECHA VCTO, ADJUNTAR FICHA TÉCNICA Y/O REGISTRO ISP, TIPO DE TRASLADO (ESPECIFICAR, PARA ACORDAR RETIRO CARGO HOSPITAL DE SER NECESARIO), E INDICAR SI CUENTA CON STOCK PARA DESPACHO INMEDIATO. SE DESESTIMARÁ OFERTA QUE INDIQUE VALOR REFERENCIAL $0 o $1, U OMITAN INFORMACIÓN. | X26: 51191603 | Y26: 77.423.498-5 | Z26: COSTO FLETE INCLUIDO, DESPACHO DE 24 A 48 HORAS, UNA VEZ ACEPTADA LA ORDEN DE COMPRA, SIN MÍNIMO DE FACTURACIÓN, VENCE SUPERIOR A 12 MESES (DSR) dsanchezr@acquainversiones.cl contacto +569 3582 9651
A27: 1058012-7412-AG25 | B27: 45967 | C27: COMITÉ FARMACIA JUNIO / DEUCRAVACITINIB 6 MG CM | D27: PEDIDO COMITÉ FARMACIA JUNIO. ADQUISICIÓN VÍA COMPRA ÁGIL. DESPACHO 3 DÍAS CARGO DEL PROVEEDOR SEGÚN COTIZACIÓN. REF 1058012-398-COT25. | E27: 5626560 | F27: 0 | G27: 0 | H27: 1069046.4 | I27: 6695606.4 | J27: Fármarcos | K27: FARMACIAS PEDRO ITURRIETA MELENDEZ E.I.R.L. | L27: 76.764.759-K | N27: Pequeña | O27: Región Metropolitana de Santiago | P27: 85121902 | Q27: DEUCRAVACITINIB 6 MG CM | R27: 240 | S27: Comprimido | T27: 23444 | U27: 5626560 | V27: 1058012-398-COT25 | W27: EL HOSPITAL CLÍNICO DE MAGALLANES REQUIERE DEUCRAVACITINIB 6 MG CM. INDICAR AL COTIZAR: VALOR UNITARIO TOTAL, PRESENTACIÓN (CM), FECHA VCTO, ADJUNTAR FICHA TÉCNICA Y/O REGISTRO ISP, TIPO DE TRASLADO Y FECHA ESPECIFICA DE ENTREGA (ESPECIFICAR, PARA ACORDAR RETIRO CARGO HOSPITAL DE SER NECESARIO), E INDICAR SI CUENTA CON STOCK PARA DESPACHO INMEDIATO. SE DECLARARÁ INADMISIBLE OFERTA QUE INDIQUE VALOR REFERENCIAL $0 o $1, U OMITAN INFORMACIÓN Y DOCUMENTOS SOLICITADOS. | X27: 85121902 | Y27: 76.764.759-K | Z27: SOTYKTU 6 MG X 30 COMP. vence 10/26 despacho GRATIS 48 horas una vez aceptada al OC se adjunta ficha fono: 992657125
A28: 1058012-6888-AG25 | B28: 45777 | C28: FALTA CENABAST MARZO / CICLOFOSFAMIDA 1G FA POLVO LIOFILIZADO | D28: PEDIDO FALTA CENABAST MARZO SIN RECEPCION. COMPRA AGIL DESPACHO 2 DIAS CARGO DEL PROVEEDOR. (DE ACUERDO A LO OFERTADO) 1058012-235-COT25 | E28: 637140 | F28: 0 | G28: 0 | H28: 121056.6 | I28: 758196.6 | J28: Fármarcos | K28: ADN FARMACEUTICA SPA | L28: 76.786.297-0 | M28: DROGUERIA | N28: Mediana | O28: Región Metropolitana de Santiago | P28: 51111507 | Q28: CICLOFOSFAMIDA 1G FA POLVO LIOFILIZADO | R28: 30 | S28: Frasco Ampolla | T28: 21238 | U28: 637140 | V28: 1058012-235-COT25 | W28: EL HCM REQUIERE CICLOFOSFAMIDA 1G FA POLVO LIOFILIZADO. INDICAR FECHA DE ENTREGA EN BODEGA HCM, FACTOR EMPAQUE, FECHA VCTO, ADJUNTAR FICHA TÉCNICA Y/O REGISTRO ISP, TIPO DE TRASLADO. POSTULAR SOLO SI CUENTA CON STOCK PARA DESPACHO INMEDIATO. COMPRA SUJETA A MULTA DE NO RESPETAR FECHA ESTIMADA DE ENTREGA. SE DESESTIMARÁ OFERTA QUE INDIQUE VALOR REFERENCIAL $0 o $1. SE DEJARA INADMISIBLE LA OFERTA QUE SOBREPASE EL VALOR DEL MONTO ESTIMADO O NO CUMPLA CON LOS DIAS Y DOC. SOLICITADOS. | X28: 51111507 | Y28: 76.786.297-0 | Z28: ENDOXAN AMP. 1GR. CX1 CICLOFOSFAMIDA ENTREGA DE 24 A 48 HRS, VENCE MAS DE 12 MESES, DESPACHO C/FACTURA INCLUIDO EN EL PRECIO, SIN MINIMO DE COMPRA,CON POLITICA DE CANJE, OFERENTE Ximena Silva/9-57438894/xsilva@adnfarmaceutica.cl
A29: 1058012-7861-AG25 | B29: 45755 | C29: FARMACIA AMBULATORIA JULIO-DICIEMBRE / LEVETIRACETAM 100 MG ML | D29: PEDIDO FARMACIA AMBULATORIA JULIO-DICIEMBRE. ADQUISICIÓN VÍA COMPRA ÁGIL. DESPACHO 72 HORAS HÁBILES CARGO DEL PROVEEDOR SEGÚN COTIZACIÓN. REF 1058012-494-COT25. | E29: 540000 | F29: 0 | G29: 0 | H29: 102600 | I29: 642600 | J29: Fármarcos | K29: GLAXOSMITHKLINE CHILE FARMACEUTICA LIMITADA | L29: 85.025.700-0 | M29: FABRICACION DE PRODUCTOS FARMACEUTICOS, SUSTANCIAS QUIMICAS MEDICINALE | N29: Grande | O29: Región Metropolitana de Santiago | P29: 51141518 | Q29: LEVETIRACETAM 100 MG ML TIPO KEPPRA | R29: 30 | S29: Frasco | T29: 18000 | U29: 540000 | V29: 1058012-494-COT25 | W29: EL HOSPITAL CLÍNICO DE MAGALLANES REQUIERE LEVETIRACETAM 100 MG ML TIPO KEPPRA. INDICAR AL COTIZAR: VALOR UNITARIO TOTAL, PRESENTACIÓN (FC), FECHA VCTO, ADJUNTAR FICHA TÉCNICA Y/O REGISTRO ISP, TIPO DE TRASLADO (ESPECIFICAR, PARA ACORDAR RETIRO CARGO HOSPITAL DE SER NECESARIO), E INDICAR SI CUENTA CON STOCK PARA DESPACHO INMEDIATO. SE DECLARARÁ INADMISIBLE OFERTA QUE INDIQUE VALOR REFERENCIAL $0 o $1, U OMITAN INFORMACIÓN Y/O DOCUMENTOS SOLICITADOS. | X29: 51141518 | Y29: 85.025.700-0 | Z29: Validez de la oferta 90 días. Facturación mínima $500.000.- neto. Vencimiento superior a doce meses, ENTREGA: 72 Horas hábiles una vez aceptada la orden de compra. Condiciones Comerciales punto 10, Flete incluido. contacto gsk.ordenesdecompra@gsk.com
A30: 1058012-8222-AG25 | B30: 45697 | C30: FARMACIA AMBULATORIA AGOSTO / CARBAMAZEPINA 100 MG 5 ML SO JBE | D30: PEDIDO FARMACIA AMBULATORIA AGOSTO. REF 1058012-533-COT25. DESPACHO 72 HORAS CARGO DEL PROVEEDOR SEGÚN COTIZACIÓN. ZGEN 100005816. | E30: 338000 | F30: 0 | G30: 0 | H30: 64220 | I30: 402220 | J30: Fármarcos | K30: LABORATORIO ACONFAR CHILE LIMITADA | L30: 76.125.564-9 | M30: SERVICIOS DE ENVASADO Y EMPAQUE| OTROS PROFESIONALES DE LA SALUD| OTRAS ACTIVIDADES EMPRESARIALES RELACIONADAS CON LA SALUD HUMANA | N30: Pequeña | O30: Región Metropolitana de Santiago | P30: 85121902 | Q30: CARBAMAZEPINA 100 MG 5 ML SO JBE | R30: 20 | S30: Frasco | T30: 16900 | U30: 338000 | V30: 1058012-533-COT25 | W30: EL HOSPITAL CLÍNICO DE MAGALLANES REQUIERE CARBAMAZEPINA 100 MG 5 ML SO JBE (TIPO TEGRETAL). INDICAR AL COTIZAR: VALOR UNITARIO TOTAL, PRESENTACIÓN (FCO), FECHA VCTO, ADJUNTAR FICHA TÉCNICA Y/O REGISTRO ISP, TIPO DE TRASLADO Y FECHA ESPECIFICA DE ENTREGA (ESPECIFICAR, PARA ACORDAR RETIRO CARGO HOSPITAL DE SER NECESARIO), E INDICAR SI CUENTA CON STOCK PARA DESPACHO INMEDIATO. SE DECLARARÁ INADMISIBLE OFERTA QUE INDIQUE VALOR REFERENCIAL $0 o $1, U OMITAN INFORMACIÓN Y DOCUMENTOS SOLICITADOS. | X30: 85121902 | Y30: 76.125.564-9 | Z30: JT FACTURAC. MÍN. $ 50.000+IVA STGO $ 75.000+IVA REGIONES. SI MONTO SUPERA 100 UTM, SE SUBIRÁN A $ 1 PARA OFERTAR.PLAZO ENTREGA STGO.24-48 hrs. REGIONES 48-72 hrs. (según cobertura O.L) FAVOR RESPETAR FACTOR EMPAQUE (para comp. inyectables y sueros).
A31: 1058012-6779-AG25 | B31: 45763 | C31: FARMACIA AMBULATORIA ABRIL / BIFIDOBACTERIUM BB-12 PROBIOTICOS EN GOTAS | D31: PEDIDO FARMACIA AMBULATORIA ABRIL. ADQUISICIÓN VÍA COMPRA ÁGIL. DESPACHO 72 HRS CARGO DEL PROVEEDOR SEGÚN COTIZACIÓN. REF 1058012-220-COT25. | E31: 1000620 | F31: 0 | G31: 0 | H31: 190117.8 | I31: 1190737.8 | J31: Fármarcos | K31: LABORATORIO ACONFAR CHILE LIMITADA | L31: 76.125.564-9 | M31: SERVICIOS DE ENVASADO Y EMPAQUE| OTROS PROFESIONALES DE LA SALUD| OTRAS ACTIVIDADES EMPRESARIALES RELACIONADAS CON LA SALUD HUMANA | N31: Pequeña | O31: Región Metropolitana de Santiago | P31: 51191905 | Q31: BIFIDOBACTERIUM BB-12 PROBIOTICOS EN GOTAS | R31: 60 | S31: Frasco | T31: 16677 | U31: 1000620 | V31: 1058012-220-COT25 | W31: EL HOSPITAL CLÍNICO DE MAGALLANES REQUIERE BIFIDOBACTERIUM BB-12 PROBIOTICOS EN GOTAS. INDICAR AL COTIZAR: VALOR UNITARIO TOTAL, PRESENTACIÓN (ML), FECHA VCTO, ADJUNTAR FICHA TÉCNICA Y/O REGISTRO ISP, TIPO DE TRASLADO (ESPECIFICAR, PARA ACORDAR RETIRO CARGO HOSPITAL DE SER NECESARIO), E INDICAR SI CUENTA CON STOCK PARA DESPACHO INMEDIATO. SE DECLARARÁ INADMISIBLE OFERTA QUE INDIQUE VALOR REFERENCIAL $0 o $1, U OMITAN CUALQUIER INFORMACIÓN SOLICITADA PARA ESTA COTIZACIÓN. | X31: 51191905 | Y31: 76.125.564-9 | Z31: JOR. FACTURACION MINIMA $50.000+IVA PARA SANTIAGO Y $75.000+IVA PARA REGIONES, DESPACHO: STGO 24-48 HR Y REGIONES 72 HR, UNIDAD MIN. COTIZADA, SE AJUSTARÁ A FACTOR DE EMPAQUE, REG.ISP, FACT.ELECTRONICA. STOCK DISPONIBLE PARA ENTREGA INMEDIATA.
A32: 1058012-7012-AG25 | B32: 45996 | C32: DERMATOLOGÍA COMITÉ FARMACIA MAYO / IMIQUIMOD 5% CREMA | D32: PEDIDO DERMATOLOGÍA COMITÉ FARMACIA MAYO. ADQUISICIÓN VÍA COMPRA ÁGIL. DESPACHO 7 DÍAS CARGO DEL PROVEEDOR SEGÚN COTIZACIÓN. REF 1058012-296-COT25. | E32: 325440 | F32: 0 | G32: 0 | H32: 61833.6 | I32: 387273.6 | J32: Fármarcos | K32: SCM PHARMA SPA | L32: 77.337.544-5 | M32: VENTA AL POR MAYOR DE PRODUCTOS FARMACEUTICOS Y MEDICINALES | N32: Mediana | O32: Región Metropolitana de Santiago | P32: 51201510 | Q32: IMIQUIMOD 5% CREMA | R32: 20 | S32: Unidad | T32: 16272 | U32: 325440 | V32: 1058012-296-COT25 | W32: EL HOSPITAL CLÍNICO DE MAGALLANES REQUIERE IMIQUIMOD 5% CREMA. INDICAR AL COTIZAR: VALOR UNITARIO TOTAL, PRESENTACIÓN (UD), FECHA VCTO, ADJUNTAR FICHA TÉCNICA Y/O REGISTRO ISP, TIPO DE TRASLADO (ESPECIFICAR, PARA ACORDAR RETIRO CARGO HOSPITAL DE SER NECESARIO), E INDICAR SI CUENTA CON STOCK PARA DESPACHO INMEDIATO. SE DECLARARÁ INADMISIBLE OFERTA QUE INDIQUE VALOR REFERENCIAL $0 o $1, U OMITAN INFORMACIÓN SOLICITADA. | X32: 51201510 | Y32: 77.337.544-5 | Z32: Se adjunta cotización detallada, Contacto F. 225104550, contacto@scmpharma.cl, Despacho sin costo, Envio 7 dias- monto mínimo de despacho $ 100.000.- Cotización valida por 15 días.
A33: 1058012-4493-AG25 | B33: 45750 | C33: COMPRA ALTERNATIVA FALTA CENABAST FEBRERO / AZITROMICINA 500 MG IV | D33: COMPRA ALTERNATIVA POR FALTA DE STOCK EN OC N° 1058012-4414-SE25. ADQUISICIÓN VÍA COMPRA ÁGIL. DESPACHO 3 DÍAS SEGÚN COTIZACIÓN. ZGEN 100004661. REF 1058012-119-COT25. | E33: 796250 | F33: 0 | G33: 0 | H33: 151287.5 | I33: 947537.5 | J33: Fármarcos | K33: EMCURE PHARMA CHILE SPA | L33: 77.240.238-4 | M33: FABRICACION DE PRODUCTOS FARMACEUTICOS, SUSTANCIAS QUIMICAS MEDICINALE | N33: Mediana | O33: Región Metropolitana de Santiago | P33: 51101572 | Q33: AZITROMICINA 500 MG IV | R33: 50 | S33: Unidad | T33: 15925 | U33: 796250 | V33: 1058012-119-COT25 | W33: EL HOSPITAL CLÍNICO DE MAGALLANES REQUIERE AZITROMICINA 500 MG IV. INDICAR AL COTIZAR: VALOR UNITARIO TOTAL, PRESENTACIÓN (UD), FECHA VCTO, ADJUNTAR FICHA TÉCNICA Y/O REGISTRO ISP, TIPO DE TRASLADO CARGO PROVEEDOR (ESPECIFICAR, PARA ACORDAR RETIRO CARGO HOSPITAL DE SER NECESARIO), E INDICAR SI CUENTA CON STOCK PARA DESPACHO INMEDIATO. SE DESESTIMARÁ OFERTA QUE INDIQUE VALOR REFERENCIAL $0 o $1, U OMITAN INFORMACIÓN Y DOCUMENTOS SOLICITADOS. | X33: 51101572 | Y33: 77.240.238-4 | Z33: AZITROMICINA LIOFILIZADO PARA SOLUCIÓN INYECTABLE 500MG FAM, FACTOR EMPAQUE X 10 FAM. EQUIVALENTE TERAPÉUTICO, Registro ISP F-27542/23, Vencimiento 07-2026 Stock disponible, entrega en 3 días - flete incluido. Datos de contacto en cotización adjunta.
A34: 1058012-4622-AG25 | B34: 45964 | C34: FARMACIA DOSIS UNITARIA NEONATOLOGIA/ BIFIDOBACTERIUM, BB-12 PROBIOTICOS EN GOTAS | D34: PEDIDO FARMACIA DOSIS UNITARIA NEONATOLOGIA. COMPRA AGIL DESPACHO, CARGO DEL PROVEEDOR. 1058012-135-COT25 | E34: 303220 | F34: 0 | G34: 0 | H34: 57611.8 | I34: 360831.8 | J34: Fármarcos | K34: FARMACEUTICA CARIBEAN LTDA | L34: 76.830.090-9 | M34: VENTA AL POR MAYOR DE ARTICULOS DE PERFUMERIA, COSMETICOS, JABONES Y P| VENTA AL POR MAYOR DE PRODUCTOS FARMACEUTICOS| ALMACENES MEDIANOS (VENTA DE ALIMENTOS) SUPERMERCADOS, MINIMARKETS| VENTA AL POR MENOR DE PRODUCTOS MEDICINALES| VENTA AL POR MENOR DE | N34: Grande | O34: Región Metropolitana de Santiago | P34: 51191905 | Q34: BIFIDOBACTERIUM, BB-12 PROBIOTICOS EN GOTAS | R34: 20 | S34: Frasco | T34: 15161 | U34: 303220 | V34: 1058012-135-COT25 | W34: EL HOSPITAL CLÍNICO DE MAGALLANES REQUIERE BIFIDOBACTERIUM, BB-12 PROBIOTICOS EN GOTAS. INDICAR AL COTIZAR: VALOR UNITARIO TOTAL, PRESENTACIÓN (ML), FECHA VCTO, ADJUNTAR FICHA TÉCNICA Y/O REGISTRO ISP, TIPO DE TRASLADO (ESPECIFICAR, PARA ACORDAR RETIRO CARGO HOSPITAL DE SER NECESARIO), E INDICAR SI CUENTA CON STOCK PARA DESPACHO INMEDIATO. SE DESESTIMARÁ OFERTA QUE INDIQUE VALOR REFERENCIAL $0 o $1, U OMITAN INFORMACIÓN. | X34: 51191905 | Y34: 76.830.090-9 | Z34: FACTURACION MINIMA $50.000+IVA PARA SANTIAGO Y $75.000+IVA PARA REGIONES, DESPACHO: STGO 24-48 HR Y REGIONES 48-72 HRS, FLETE ADICIONALSOLO SUEROS X VOLUMEN, UNIDAD MIN. COTIZADA, SE AJUSTARÁ A FACTOR DE EMPAQUE, REG.ISP, FACT.ELECTRONICA.
A35: 1058012-4686-AG25 | B35: 45736 | C35: FALTA CENABAST MARZO / CICLOFOSFAMIDA 1G FA POLVO LIOFILIZADO | D35: PEDIDO FALTA DISTRIBUCIÓN CENABAST MARZO. ADQUISICIÓN VÍA COMPRA ÁGIL. DESPACH0O 24 A 48 HRS. SEGÚN COTIZACIÓN. ZGEN 100000371. REF 1058012-146-COT25. | E35: 990080 | F35: 0 | G35: 0 | H35: 188115.2 | I35: 1178195.2 | J35: Fármarcos | K35: ADN FARMACEUTICA SPA | L35: 76.786.297-0 | M35: DROGUERIA | N35: Mediana | O35: Región Metropolitana de Santiago | P35: 51111507 | Q35: CICLOFOSFAMIDA 1G FA POLVO LIOFILIZADO | R35: 70 | S35: Frasco Ampolla | T35: 14144 | U35: 990080 | V35: 1058012-146-COT25 | W35: EL HOSPITAL CLÍNICO DE MAGALLANES REQUIERE CICLOFOSFAMIDA 1G FA POLVO LIOFILIZADO. INDICAR AL COTIZAR: VALOR UNITARIO TOTAL, PRESENTACIÓN (ML), FECHA VCTO, ADJUNTAR FICHA TÉCNICA Y/O REGISTRO ISP, TIPO DE TRASLADO (ESPECIFICAR, PARA ACORDAR RETIRO CARGO HOSPITAL DE SER NECESARIO), E INDICAR SI CUENTA CON STOCK PARA DESPACHO INMEDIATO. SE DECLARARA INADMISIBLE OFERTA QUE INDIQUE VALOR REFERENCIAL $0 o $1, NO ENTREGUEN DOCUMENTACIÓN TÉCNICA U OMITAN INFORMACIÓN. | X35: 51111507 | Y35: 76.786.297-0 | Z35: ENDOXAN 1 G SOL. INY. X 50 ML, COSTO FLETE INCLUIDO, DESPACHO DE 24 A 48 HORAS, UNA VEZ ACEPTADA LA ORDEN DE COMPRA, SIN MÍNIMO DE FACTURACIÓN, VENCE SUPERIOR A 12 MESES (PV) pvalencia@adnfarmaceutica.cl
A36: 1058012-7676-AG25 | B36: 45907 | C36: FALTA CENABAST JULIO (FALTANTE) / CICLOFOSFAMIDA 1G FA POLVO LIOFILIZADO | D36: PEDIDO FALTA CENABAST JULIO (FALTANTE). ADQUISICIÓN VÍA COMPRA ÁGIL. DESPACHO 3 DÍAS CARGO DEL PROVEEDOR SEGÚN COTIZACIÓN. ZGEN 100000371. REF 1058012-437-COT25. | E36: 424320 | F36: 0 | G36: 0 | H36: 80620.8 | I36: 504940.8 | J36: Fármarcos | K36: ADN FARMACEUTICA SPA | L36: 76.786.297-0 | M36: DROGUERIA | N36: Mediana | O36: Región Metropolitana de Santiago | P36: 51111507 | Q36: CICLOFOSFAMIDA 1G FA POLVO LIOFILIZADO | R36: 30 | S36: Frasco Ampolla | T36: 14144 | U36: 424320 | V36: 1058012-437-COT25 | W36: EL HCM REQUIERE CICLOFOSFAMIDA 1G FA POLVO LIOFILIZADO. INDICAR FECHA DE ENTREGA EN BODEGA HCM, FACTOR EMPAQUE, FECHA VCTO, ADJUNTAR FICHA TÉCNICA Y/O REGISTRO ISP, TIPO DE TRASLADO. POSTULAR SOLO SI CUENTA CON STOCK PARA DESPACHO INMEDIATO. COMPRA SUJETA A MULTA DE NO RESPETAR FECHA ESTIMADA DE ENTREGA. SE DESESTIMARÁ OFERTA QUE INDIQUE VALOR REFERENCIAL $1, O QUE SOBREPASE EL VALOR DEL MONTO ESTIMADO O NO CUMPLA CON LOS DIAS Y DOC. SOLICITADOS. | X36: 51111507 | Y36: 76.786.297-0 | Z36: ENDOXAN 1 G SOL. INY. X 50 ML*ENTREGA DE 24 A 48 HRS, VENCE MAS DE 12 MESES, DESPACHO C/FACTURA, DESPACHO INCLUIDO EN EL PRECIO, SIN MINIMO DE COMPRA,CON POLITICA DE CANJE, OFERENTE Ximena Silva/9-57438894/xsilva@adnfarmaceutica.cl
A37: 1058012-7672-AG25 | B37: 45876 | C37: COMPRA ALTERNATIVA FALTA CENABAST MAYO Y JUNIO / LACTULOSA 65-66 1000 ML | D37: COMPRA ALTERNATIVA POR FALTA DE STOCK EN PROVEEDOR OC N° 1058012-7047-SE25 Y OC N° 1058012-7423-SE25. ADQUISICIÓN VÍA COMPRA ÁGIL. DESPACHO 7 DÍAS CARGO DEL PROVEEDOR SEGÚN COTIZACIÓN. ZGEN 100000893. REF 1058012-452-COT25. | E37: 2898000 | F37: 0 | G37: 0 | H37: 550620 | I37: 3448620 | J37: Fármarcos | K37: SCM PHARMA SPA | L37: 77.337.544-5 | M37: VENTA AL POR MAYOR DE PRODUCTOS FARMACEUTICOS Y MEDICINALES | N37: Mediana | O37: Región Metropolitana de Santiago | P37: 51171605 | Q37: LACTULOSA 65-66 1000 ML | R37: 210 | S37: Litro | T37: 13800 | U37: 2898000 | V37: 1058012-452-COT25 | W37: EL HOSPITAL CLÍNICO DE MAGALLANES REQUIERE LACTULOSA 65-66 1000 ML. INDICAR AL COTIZAR: VALOR UNITARIO TOTAL, PRESENTACIÓN (LT), FECHA VCTO, ADJUNTAR FICHA TÉCNICA Y/O REGISTRO ISP, TIPO DE TRASLADO Y FECHA ESPECIFICA DE ENTREGA (ESPECIFICAR, PARA ACORDAR RETIRO CARGO HOSPITAL DE SER NECESARIO), E INDICAR SI CUENTA CON STOCK PARA DESPACHO INMEDIATO. SE DECLARARÁ INADMISIBLE OFERTA QUE INDIQUE VALOR REFERENCIAL $0 o $1, U OMITAN INFORMACIÓN Y DOCUMENTOS SOLICITADOS. | X37: 51171605 | Y37: 77.337.544-5 | Z37: Se adjunta cotización detallada, Contacto F. 225104550, contacto@scmpharma.cl, Despacho sin costo, Envio 7 dias- monto mínimo de despacho $ 100.000.- Cotización valida por 15 días.
A38: 1058012-1372-AG24 | B38: 45571 | C38: FARMACIA AMBULATORIA JUNIO / CARBAMAZEPINA 100 MG 5ML SO | D38: PEDIDO FARMACIA AMBULATORIA JUNIO. ADQUISICIÓN VÍA COMPRA ÁGIL. FLETE CARGO DEL PROVEEDOR. ZGEN 100005816. REF 1058012-402-COT24. | E38: 619200 | F38: 0 | G38: 0 | H38: 117648 | I38: 736848 | J38: Fármarcos | K38: NOVOFARMA SERVICE S A | L38: 96.945.670-2 | M38: SERVICIOS DE ALMACENAMIENTO Y DEPOSITO| OTRAS ACTIVIDADES EMPRESARIALES N.C.P. | N38: Grande | O38: Región Metropolitana de Santiago | P38: 51141513 | Q38: CARBAMAZEPINA 100 MG 5ML SOLUCIÓN ORAL | R38: 48 | S38: Frasco | T38: 12900 | U38: 619200 | V38: 1058012-402-COT24 | W38: EL HOSPITAL CLÍNICO DE MAGALLANES REQUIERE CARBAMAZEPINA 100 MG 5ML SO. INDICAR AL COTIZAR: VALOR UNITARIO TOTAL, PRESENTACIÓN (ML), FECHA VCTO, ADJUNTAR FICHA TÉCNICA Y/O REGISTRO ISP, TIPO DE TRASLADO CARGO PROVEEDOR CON DESPACHOS PARCIALIZADOS (ESPECIFICAR, PARA ACORDAR RETIRO CARGO HOSPITAL DE SER NECESARIO), E INDICAR SI CUENTA CON STOCK PARA DESPACHO INMEDIATO. SE DESESTIMARÁ OFERTA QUE INDIQUE VALOR REFERENCIAL $0 o $1, U OMITAN INFORMACIÓN. | X38: 51141513 | Y38: 96.945.670-2 | Z38: AX3003800 - TEGRETAL JARABE 2% 100ML - F-4378/20 - CARBAMAZEPINA - - FRASCO 100 ML - EFICACIA DE 36 MESES ALMACENADO A NO MÁS DE 25ºC - LOTE ACTUAL VENCE 31/08/2026 DESPACHO INMEDIATO- SIN REGARGO POR FLETE- MINIMO DE DESPACHO 7 UF + IVA.
A39: 1058012-6777-AG25 | B39: 45763 | C39: COMPRA ALTERNATIVA STOCK CRÍTICO FARMACIA DOSIS UNITARIA / AMINOACIDOS 10% PARA ADMINISTRACION I.V. | D39: COMPRA ALTERNATIVA STOCK CRÍTICO FARMACIA DOSIS UNITARIA EN PROVEEDOR DE N° ORDEN 1058012-6645-SE25. ADQUISICIÓN VÍA COMPRA ÁGIL. TRASLADO AEREO CARGO DEL PROVEEDOR ZGEN 100000114 REF 1058012-204-COT25 | E39: 1278800 | F39: 0 | G39: 0 | H39: 242972 | I39: 1521772 | J39: Fármarcos | K39: FRESENIUS KABI CHILE LIMITADA | L39: 77.478.120-k | M39: VENTA AL POR MAYOR DE PRODUCTOS FARMACEUTICOS| TRANSPORTE DE CARGA POR CARRETERA| EMPRESAS DE ASESORIA, CONSULTORIA FINANCIERA Y DE APOYO AL GIRO | N39: Grande | O39: Región Metropolitana de Santiago | P39: 51191902 | Q39: AMINOACIDOS 10% PARA ADMINISTRACION I.V. | R39: 100 | S39: Unidad | T39: 12788 | U39: 1278800 | V39: 1058012-204-COT25 | W39: EL HOSPITAL CLÍNICO DE MAGALLANES REQUIERE AMINOACIDOS 10% PARA ADMINISTRACION I.V. INDICAR AL COTIZAR: VALOR UNITARIO TOTAL, PRESENTACIÓN (UD), FECHA VCTO, ADJUNTAR FICHA TÉCNICA Y/O REGISTRO ISP, TIPO DE TRASLADO (ESPECIFICAR, PARA ACORDAR RETIRO CARGO HOSPITAL DE SER NECESARIO), E INDICAR SI CUENTA CON STOCK PARA DESPACHO INMEDIATO. SE DECLARARÁ INADMISIBLE OFERTA QUE INDIQUE VALOR REFERENCIAL $0 o $1, U OMITAN CUALQUIER INFORMACIÓN SOLICITADA PARA ESTA COTIZACIÓN. | X39: 51191902 | Y39: 77.478.120-k | Z39: Cotización_0020178566. Despacho en caja según factor de empaque. Vencimiento de material 04.07.2026.
... A47: 1058012-2089-AG24 | B47: 45533 | C47: STOCK CRÍTICO FARMACIA AMBULATORIA AGOSTO / BUDESONIDA FORMOTEROL FUMARATO 160/4,5 MCG BUCAL | D47: PEDIDO STOCK CRÍTICO FARMACIA AMBULATORIA AGOSTO. ADQUISICIÓN VÍA COMPRA ÁGIL. FLETE 2 A 3 DÍAS HÁBILES CARGO DEL PROVEEDOR SEGÚN COTIZACIÓN. REF 1058012-543-COT24. | E47: 1087300 | F47: 0 | G47: 0 | H47: 206587 | I47: 1293887 | J47: Fármarcos | K47: ASTRAZENECA SA | L47: 76.447.530-5 | M47: VENTA AL POR MAYOR DE PRODUCTOS FARMACEUTICOS | N47: Grande | O47: Región Metropolitana de Santiago | P47: 51161703 | Q47: BUDESONIDA FORMOTEROL FUMARATO 160/4,5 MCG BUCAL | R47: 100 | S47: Unidad | T47: 10873 | U47: 1087300 | V47: 1058012-543-COT24 | W47: EL HOSPITAL CLÍNICO DE MAGALLANES REQUIERE BUDESONIDA FORMOTEROL FUMARATO 160/4,5 MCG BUCAL. INDICAR AL COTIZAR: VALOR UNITARIO TOTAL, PRESENTACIÓN (UD), FECHA VCTO, ADJUNTAR FICHA TÉCNICA Y/O REGISTRO ISP, TIPO DE TRASLADO CARGO PROVEEDOR (ESPECIFICAR, PARA ACORDAR RETIRO CARGO HOSPITAL DE SER NECESARIO), E INDICAR SI CUENTA CON STOCK PARA DESPACHO INMEDIATO. SE DESESTIMARÁ OFERTA QUE INDIQUE VALOR REFERENCIAL $0 o $1, U OMITAN INFORMACIÓN Y DOCUMENTOS SOLICITADOS. | X47: 51161703 | Y47: 76.447.530-5 | Z47: Fármaco innovador y/o referente. Venc > 1 año, despacho 2-3 días hábiles desde aceptación de orden de compra. Flete incluido. Cuando genere su OC, el rut de compra y dirección de despacho deben poseer autorización sanitaria vigente.
A48: 1058012-2875-AG24 | B48: 45547 | C48: FARMACIA DOSIS UNITARIA DICIEMBRE / KETAMINA 500 MG 10 ML SOL INY FA | D48: PEDIDO FARMACIA DOSIS UNITARIA DICIEMBRE. ADQUISICIÓN VÍA COMPRA ÁGIL. FLETE CARGO DEL PROVEEDOR. ZGEN 100000865. REF 1058012-662-COT24. | E48: 257500 | F48: 0 | G48: 0 | H48: 48925 | I48: 306425 | J48: Fármarcos | K48: CRISTALIA CHILE SPA | L48: 77.542.429-K | N48: N/A | O48: Región Metropolitana de Santiago | P48: 51142934 | Q48: KETAMINA SOL INY 500 MG/10 ML | R48: 25 | S48: Frasco Ampolla | T48: 10300 | U48: 257500 | V48: 1058012-662-COT24 | W48: EL HOSPITAL CLÍNICO DE MAGALLANES REQUIERE KETAMINA SOL INY 500 MG/10 ML. INDICAR AL COTIZAR: VALOR UNITARIO TOTAL, PRESENTACIÓN (ML), FECHA VCTO, ADJUNTAR FICHA TÉCNICA Y/O REGISTRO ISP, TIPO DE TRASLADO y ESPECIFICAR FECHA DE ENTREGA, INDICAR SI CUENTA CON STOCK PARA DESPACHO INMEDIATO. SE DESESTIMARÁ OFERTA QUE INDIQUE VALOR REFERENCIAL $0 o $1, U OMITAN INFORMACIÓN. | X48: 51142934 | Y48: 77.542.429-K | Z48: -ESKETAMINA MARCA KETA-S 50MG/ML 25FA 10 ML POR LABORATORIO CRISTALIA (PRESENTACION 25 FRASCO AMPOLLA POR CAJA) VENCIMIENTO SUPERIOR A 12 MESES DISTRIBUCION DESDE 23-12-2024
A49: 1057402-6386-AG24 | B49: 45464 | C49: (FAR) ANTISEPTICOS Y DESINFECTANTES JUNIO / CLORHEXIDINA 5% TINTURA 125 ML | D49: PEDIDO ANTISEPTICOS Y DESINFECTANTES JUNIO. ADQUISICIÓN VÍA COMPRA ÁGIL. FLETE 3 A 5 DÍAS HÁBILES SEGÚN COTIZACIÓN. REF 1057402-936-COT24 | E49: 720000 | F49: 0 | G49: 0 | H49: 136800 | I49: 856800 | J49: Bienes y Servicios | K49: EQUIPOS MÉDICOS CHILE SPA | L49: 77.354.084-5 | N49: Pequeña | O49: Región Metropolitana de Santiago | P49: 42281601 | Q49: CLORHEXIDINA 5% TINTURA 125 ML | R49: 72 | S49: Unidad | T49: 10000 | U49: 720000 | V49: 1057402-936-COT24 | W49: SE REQUIERE PARA EL HOSPITAL CLÍNICO DE MAGALLANES CLORHEXIDINA 5% TINTURA 125 ML. INDICAR: VALOR UNITARIO, PRESENTACIÓN Y EMPAQUE (ML), FECHA VCTO, ADJUNTAR FICHA TÉCNICA Y/O REGISTRO ISP, IMAGEN DEL PRODUCTO, TIEMPO DE ENTREGA (ESPECIFICAR, PARA COORDINAR RETIRO CARGO HOSPITAL DE SER NECESARIO), E INDICAR SI CUENTA CON STOCK PARA DESPACHO INMEDIATO. NO SE CONSIDERARÁN OFERTAS QUE INDIQUEN VALOR REFERENCIAL $0 Ó $1 U OMITAN INFORMACIÓN. | X49: 42281601 | Y49: 77.354.084-5 | Z49: SE ADJUNTA FICHA TÉCNICA DE LA OFERTA, INCLUYE LA TOTALIDAD DE LA SOLICITUD. ENTREGA 3 A 5 DÍAS HÁBILES. ANTE DUDAS FAVOR CONTACTARME c.calderon@equiposmedicoschile.cl +56937621017 CATALINA CALDERÓ
A50: 1058012-1537-AG24 | B50: 45468 | C50: COMPRA ALTERNATIVA FALTA CENABAST JUNIO / LEVETIRACETAM 100 MG ML SO | D50: COMPRA ALTERNATIVA POR FALTA DE STOCK EN PROVEEDOR OC N° 1058012-1384-SE24. ADQUISICIÓN VÍA COMPRA ÁGIL. FLETE 2 DÍAS HÁBILES SEGÚN COTIZACIÓN. ZGEN 100002573. REF 1058012-428-COT24. | E50: 600000 | F50: 0 | G50: 0 | H50: 114000 | I50: 714000 | J50: Fármarcos | K50: LABORATORIOS RECALCINE SA | L50: 91.637.000-8 | M50: FABRICACION DE PRODUCTOS FARMACEUTICOS, SUSTANCIAS QUIMICAS MEDICINALE| VENTA AL POR MAYOR DE OTROS PRODUCTOS N.C.P.| OTRAS ACTIVIDADES EMPRESARIALES N.C.P. | N50: Grande | O50: Región Metropolitana de Santiago | P50: 51141518 | Q50: LEVETIRACETAM 100 MG ML SOLUCIÓN ORAL | R50: 60 | S50: Frasco | T50: 10000 | U50: 600000 | V50: 1058012-428-COT24 | W50: EL HOSPITAL CLÍNICO DE MAGALLANES REQUIERE LEVETIRACETAM 100 MG ML SO. INDICAR AL COTIZAR: VALOR UNITARIO TOTAL, PRESENTACIÓN (ML), FECHA VCTO, ADJUNTAR FICHA TÉCNICA Y/O REGISTRO ISP, TIPO DE TRASLADO CARGO PROVEEDOR (ESPECIFICAR, PARA ACORDAR RETIRO CARGO HOSPITAL DE SER NECESARIO), E INDICAR SI CUENTA CON STOCK PARA DESPACHO INMEDIATO. SE DESESTIMARÁ OFERTA QUE INDIQUE VALOR REFERENCIAL $0 o $1, U OMITAN INFORMACIÓN. | X50: 51141518 | Y50: 91.637.000-8 | Z50: 881526 KOPODEX 100MG SOL ORAL X 120 ML PA LEVETIRACETAM 100 MG REG ISP F-16138/22 VENCE 15-05-2027. PRECIO INCL. FLETE, ENTREGA 48 HRS HAB., MIN. FACT. $100.000.- STOCK DISPONIBLE, CONTACTO: SHIRLEY.BELMAR@ABBOTT.COM
...

Sheet medicamentos farmacia

Sheet CALCULOS TABLA
A7: Tabla analitica de ordenes de compra
L8: Total sin CENABAST | M8: Total sin farmacia ambulatoria | N8: Total stock critico + CENABAST | O8: Total dosis unitaria + comite farmacia | P8: Total farmacia ambulatoria
A9: Columna 1 | B9: Total stock critico | C9: Total CENABAST | D9: Total dosis unitaria | E9: Total farmacia ambulatoria | F9: Total comité farmacia | G9: Total controlados | H9: Total otros sin clasificar | I9: Total ordenes | L9: =TOTALES!C147 -> 149626460 | M9: =H10+G10+F10+D10+C10+B10 -> 140477859 | N9: =B10+C10 -> 49329647 | O9: =D10+F10 -> 54541587 | P9: 46137003
A10: Valor total con impuesto | B10: ='tabla dinamica total'!F17 -> 12341245 | C10: ='tabla dinamica total'!C47 -> 36988402 | D10: ='tabla dinamica total'!F72 -> 20394810 | E10: ='tabla dinamica total'!I58 -> 46137003 | F10: ='tabla dinamica total'!C74 -> 34146776 | G10: ='tabla dinamica total'!F24 -> 1837122 | H10: ='tabla dinamica total'!F50 -> 34769503 | I10: =SUM(B10:H10) -> 1.8661486e+08 | L10: =L9/I10 -> 0.80179284 | M10: =M9/I10 -> 0.75276887 | N10: =B11+C11 -> 0.26433933 | O10: =O9/I10 -> 0.29226818 | P10: 0.24723113
A11: Porcentaje de valor total | B11: =B10/$I$10 -> 0.066132165 | C11: =C10/$I$10 -> 0.19820716 | D11: =D10/$I$10 -> 0.10928824 | E11: =E10/$I$10 -> 0.24723113 | F11: =F10/$I$10 -> 0.18297994 | G11: =G10/$I$10 -> 0.0098444571 | H11: =H10/$I$10 -> 0.1863169
A12: Porcentaje acumulado | B12: =B11 -> 0.066132165 | C12: =B12+C11 -> 0.26433933 | D12: =C12+D11 -> 0.37362757 | E12: =D12+E11 -> 0.6208587 | F12: =E12+F11 -> 0.80383864 | G12: =F12+G11 -> 0.8136831 | H12: =G12+H11 -> 1
A13: Cantidad de datos | B13: ='tabla dinamica total'!E17 -> 15 | C13: ='tabla dinamica total'!B47 -> 46 | D13: ='tabla dinamica total'!E72 -> 20 | E13: ='tabla dinamica total'!H58 -> 56 | F13: ='tabla dinamica total'!B74 -> 25 | G13: ='tabla dinamica total'!E24 -> 5 | H13: ='tabla dinamica total'!E50 -> 26 | I13: =SUM(B13:H13) -> 193
A14: Porcentaje cantidad | B14: =B13/$I$13 -> 0.077720207 | C14: =C13/$I$13 -> 0.23834197 | D14: =D13/$I$13 -> 0.10362694 | E14: =E13/$I$13 -> 0.29015544 | F14: =F13/$I$13 -> 0.12953368 | G14: =G13/$I$13 -> 0.025906736 | H14: =H13/$I$13 -> 0.13471503 | I14: =I13/$I$13 -> 1
A15: Cantidad acumulada | B15: =B13 -> 15 | C15: =B15+C13 -> 61 | D15: =C15+D13 -> 81 | E15: =D15+E13 -> 137 | F15: =E15+F13 -> 162 | G15: =F15+G13 -> 167 | H15: =G15+H13 -> 193
A16: Porcentaje cantidad acumulada | B16: =B15/$I$13 -> 0.077720207 | C16: =C15/$I$13 -> 0.31606218 | D16: =D15/$I$13 -> 0.41968912 | E16: =E15/$I$13 -> 0.70984456 | F16: =F15/$I$13 -> 0.83937824 | G16: =G15/$I$13 -> 0.86528497 | H16: =H15/$I$13 -> 1
B17: farmacia amnbulatoria estaria gastando mas de 50 millones en 2 años si se suma el stock critico y el total cenabast, voy a hacer una suma tambien considernado solo el area de farmacia ambulatoria, que eran como 70 datos
A70: Periodo 2024-2025 | B70: Total stock critico | C70: Total CENABAST | D70: Total dosis unitaria | E70: Total farmacia ambulatoria | F70: Total comité farmacia | G70: Total controlados | H70: Total otros sin clasificar | I70: Total ordenes
A71: Valor total con impuesto | B71: 12341245 | C71: 36988402 | D71: 20394810 | E71: 46137003 | F71: 34146776 | G71: 1837122 | H71: 34769503 | I71: 1.8661486e+08
A72: Porcentaje de valor total | B72: 0.066132165 | C72: 0.19820716 | D72: 0.10928824 | E72: 0.24723113 | F72: 0.18297994 | G72: 0.0098444571 | H72: 0.1863169
A73: Porcentaje acumulado | B73: 0.066132165 | C73: 0.26433933 | D73: 0.37362757 | E73: 0.6208587 | F73: 0.80383864 | G73: 0.8136831 | H73: 1
A74: Cantidad de datos | B74: 15 | C74: 46 | D74: 20 | E74: 56 | F74: 25 | G74: 5 | H74: 26 | I74: 193
A75: Porcentaje cantidad | B75: 0.077720207 | C75: 0.23834197 | D75: 0.10362694 | E75: 0.29015544 | F75: 0.12953368 | G75: 0.025906736 | H75: 0.13471503 | I75: 1
A76: Cantidad acumulada | B76: 15 | C76: 61 | D76: 81 | E76: 137 | F76: 162 | G76: 167 | H76: 193
A77: Porcentaje cantidad acumulada | B77: 0.077720207 | C77: 0.31606218 | D77: 0.41968912 | E77: 0.70984456 | F77: 0.83937824 | G77: 0.86528497 | H77: 1
A79: 2024 | B79: Total stock critico | C79: Total CENABAST | D79: Total dosis unitaria | E79: Total farmacia ambulatoria | F79: Total comité farmacia | G79: Total controlados | H79: Total otros sin clasificar | I79: Total ordenes
A80: Valor total con impuesto | B80: ='Tabla dinámica 2024'!H10 -> 7776166.9 | C80: ='Tabla dinámica 2024'!D22 -> 8156588.4 | D80: ='Tabla dinámica 2024'!H45 -> 10531214 | E80: ='Tabla dinámica 2024'!L24 -> 15538045 | F80: ='Tabla dinámica 2024'!D42 -> 15318442 | G80: ='Tabla dinámica 2024'!H16 -> 848946 | H80: ='Tabla dinámica 2024'!H31 -> 18576543 | I80: =SUM(B80:H80) -> 76745945
A81: Porcentaje de valor total | B81: =B80/$I$80 -> 0.10132349 | C81: =C80/$I$80 -> 0.10628038 | D81: =D80/$I$80 -> 0.13722177 | E81: =E80/$I$80 -> 0.2024608 | F81: =F80/$I$80 -> 0.19959936 | G81: =G80/$I$80 -> 0.01106177 | H81: =H80/$I$80 -> 0.24205243 | I81: =I80/$I$80 -> 1
A82: Porcentaje acumulado | B82: =B81 -> 0.10132349 | C82: =B82+C81 -> 0.20760387 | D82: =C82+D81 -> 0.34482564 | E82: =D82+E81 -> 0.54728644 | F82: =E82+F81 -> 0.7468858 | G82: =F82+G81 -> 0.75794757 | H82: =G82+H81 -> 1
A83: Cantidad de datos | B83: ='Tabla dinámica 2024'!G10 -> 8 | C83: ='Tabla dinámica 2024'!C22 -> 20 | D83: ='Tabla dinámica 2024'!G45 -> 11 | E83: ='Tabla dinámica 2024'!K24 -> 22 | F83: ='Tabla dinámica 2024'!C42 -> 18 | G83: ='Tabla dinámica 2024'!G16 -> 3 | H83: ='Tabla dinámica 2024'!G31 -> 14 | I83: =SUM(B83:H83) -> 96 | L83: =I80+I89 -> 1.8661486e+08
